<?xml version="1.0"?>
<!-- Mesh file and approximate numbers are from Abe Bachrach at Skydio.  -->
<robot name="skydio_2">
  <!--
  Axes are standard vehicle coordinates:
    +X - Pointing toward the nose (primary camera).
    +Y - Towards the left rotors.
    +Z - Towards the top of the vehicle..
  Origin:
    (0, 0, 0) in the center of the main quadrotor body.
  -->
  <link name="world"/>
  <joint name="floating_base_joint" type="floating">
      <origin rpy="0 0 0" xyz="0 0 0"/>
      <parent link="world"/>
      <child link="x2"/>
  </joint>

  <link name="x2">
          <inertial>
              <origin rpy="0 0 0" xyz="0 0 0.1"/>
              <mass value="0"/>
              <inertia ixx="0" ixy="0" ixz="0" iyy="0" iyz="0" izz="0"/>
          </inertial>
          <visual>
              <origin rpy="0 0 0" xyz="0 0 0"/>
              <geometry>
                  <cylinder radius=".06" length=".025"/>
              </geometry>
          </visual>

          <collision>
              <origin rpy="0 0 0" xyz="0 0 0"/>
              <geometry>
                  <cylinder radius=".06" length=".025"/>
              </geometry>
          </collision>
      </link>

    <link name="rotor1">
        <inertial>
            <mass value="0.25"/>
            <inertia ixx="0.00085" ixy="0" ixz="0" iyy="0.00085" iyz="0" izz="0.00169"/>
        </inertial>
        <visual>
            <origin rpy="0 0 0" xyz="0 0 0"/>
            <geometry>
                <cylinder radius=".13" length=".005"/>
            </geometry>
        </visual>
    </link>
    <link name="rotor2">
        <inertial>
            <mass value="0.25"/>
            <inertia ixx="0.00085" ixy="0" ixz="0" iyy="0.00085" iyz="0" izz="0.00169"/>
        </inertial>
        <visual>
            <origin rpy="0 0 0" xyz="0 0 0"/>
            <geometry>
                <cylinder radius=".13" length=".005"/>
            </geometry>
        </visual>
    </link>
    <link name="rotor3">
        <inertial>
            <mass value="0.25"/>
            <inertia ixx="0.00085" ixy="0" ixz="0" iyy="0.00085" iyz="0" izz="0.00169"/>
        </inertial>
        <visual>
            <origin rpy="0 0 0" xyz="0 0 0"/>
            <geometry>
                <cylinder radius=".13" length=".005"/>
            </geometry>
        </visual>
    </link>
    <link name="rotor4">
        <inertial>
            <mass value="0.25"/>
            <inertia ixx="0.00085" ixy="0" ixz="0" iyy="0.00085" iyz="0" izz="0.00169"/>
        </inertial>
        <visual>
            <origin rpy="0 0 0" xyz="0 0 0"/>
            <geometry>
                <cylinder radius=".13" length=".005"/>
            </geometry>
        </visual>
    </link>
    <link name="center_of_mass_link">
        <inertial>
            <origin rpy="0 0 0" xyz="0 0 0.02"/>
            <mass value="0.325"/>
            <inertia ixx="0.00013" ixy="0" ixz="0" iyy="0.00169" iyz="0" izz="0.001768"/>
        </inertial>
    </link>

    <joint name="center_of_mass_joint" type="fixed">
        <parent link="x2"/>
        <child link="center_of_mass_link"/>
    </joint>
    <joint name="prop0_joint" type="fixed">
        <parent link="x2"/>
        <child link="rotor1"/>
        <origin rpy="0 0 0" xyz="-0.14 -0.18 0.05"/>
    </joint>
    <joint name="prop1_joint" type="fixed">
        <parent link="x2"/>
        <child link="rotor2"/>
        <origin rpy="0 0 0" xyz="-0.14 0.18 0.05"/>
    </joint>
    <joint name="prop2_joint" type="fixed">
        <parent link="x2"/>
        <child link="rotor3"/>
        <origin rpy="0 0 0" xyz="0.14 0.18 0.08"/>
    </joint>
    <joint name="prop3_joint" type="fixed">
        <parent link="x2"/>
        <child link="rotor4"/>
        <origin rpy="0 0 0" xyz="0.14 -0.18 0.08"/>
    </joint>
</robot>

  <link name="base_link_quadrotor">
    <inertial>
      <mass value="0.775"/>
      <origin xyz="0 0 0"/>
      <inertia ixx="0.0015" ixy="0.0" ixz="0.0" iyy="0.0025" iyz="0.0" izz="0.0035"/>
    </inertial>
    <visual>
      <origin rpy="1.570796 0 0" xyz="0 0 0"/>
      <geometry>
        <mesh filename="../meshes/skydio_2_1000_poly.gltf" scale=".00254"/>
      </geometry>
    </visual>
    <collision>
      <origin rpy="1.570796 0 0" xyz="0 0 0"/>
            <geometry>
        <mesh filename="../meshes/skydio_2_1000_poly.gltf" scale=".00254"/>
      </geometry>
    </collision>
  </link>
      <geometry>
        <box size=".36 .4 .06"/>
      </geometry>
