<?xml version="1.0" ?>
<robot name="cart_pole">


  <!-- Base -->
  <link name="base_link">
    <!-- <visual>
      <geometry>
        <mesh filename="../meshes/STL/base/structure.obj" scale="0.001 0.001 0.001"/>
      </geometry>
      <material name="blue">
        <color rgba="0.2 0.2 0.8 1.0"/>
      </material>
    </visual> -->
    <collision>
      <geometry>
        <mesh filename="../meshes/STL/base/structure.obj" scale="0.001 0.001 0.001"/>
      </geometry>
    </collision> 
    <inertial>
      <origin xyz="0 0 1.02"/>
      <mass value="6680"/>
      <inertia ixx="10732.34" ixy="0" ixz="0" iyy="16077.28" iyz="0" izz="8516.6"/>
    </inertial>
  </link>

  <!-- Cart -->
  <joint name="cart_joint" type="prismatic">
    <origin rpy="0 0 1.57" xyz="0 0 2.5"/>
    <parent link="base_link"/>
    <child link="cart_link"/>
    <limit effort="300000000" lower="-1.0" upper="1.0" velocity="30"/>
    <axis xyz="0 1 0"/>
  </joint>
  <link name="cart_link">
    <visual>
      <geometry>
        <mesh filename="../meshes/STL/cart/mycart.obj" scale="0.001 0.001 0.001"/>
      </geometry>
      <material name="dark_grey">
        <color rgba="0.2 0.2 0.2 1.0"/>
      </material>
    </visual>
    <collision>
      <geometry>
        <mesh filename="../meshes/STL/cart/mycart.obj" scale="0.001 0.001 0.001"/>
      </geometry>
    </collision>
    <inertial>
      <origin xyz="0 0 0"/>
      <mass value="370"/>
      <inertia ixx="11.09" ixy="0" ixz="0" iyy="12.32" iyz="0" izz="11.09"/>
    </inertial>
  </link>

  <!-- Links and Joints -->
  <joint name="joint1" type="continuous">
    <parent link="cart_link"/>
    <child link="link1"/>
    <origin rpy="0 -3.14159274 0" xyz="0 0 -0.2"/>
    <axis xyz="0 1 0"/>
  </joint>
  <transmission name="trans_1">
    <type>transmission_interface/SimpleTransmission</type>
    <joint name="joint1">
      <hardwareInterface>hardware_interface/EffortJointInterface</hardwareInterface>
    </joint>
    <actuator name="motor_1">
      <hardwareInterface>hardware_interface/EffortJointInterface</hardwareInterface>
      <mechanicalReduction>1</mechanicalReduction>
    </actuator>
  </transmission>
  <link name="link1">
    <inertial>
      <mass value="0.025"/>
      <inertia ixx="5.8083e-4" ixy="0" ixz="0" iyy="3.0833e-5" iyz="0" izz="5.9083e-4"/>
    </inertial>
  </link>

  <joint name="joint2" type="continuous">
    <parent link="link1"/>
    <child link="link2"/>
    <axis xyz="0 0 1"/>
    <origin rpy="0 0 0" xyz="0 0 0"/>
  </joint>
  <transmission name="trans_2">
    <type>transmission_interface/SimpleTransmission</type>
    <joint name="joint2">
      <hardwareInterface>hardware_interface/EffortJointInterface</hardwareInterface>
    </joint>
    <actuator name="motor_2">
      <hardwareInterface>hardware_interface/EffortJointInterface</hardwareInterface>
      <mechanicalReduction>1</mechanicalReduction>
    </actuator>
  </transmission>
  <link name="link2">
    <inertial>
      <mass value="0.025"/>
      <inertia ixx="5.8083e-4" ixy="0" ixz="0" iyy="3.0833e-5" iyz="0" izz="5.9083e-4"/>
    </inertial>
  </link>

  <joint name="joint3" type="continuous">
    <parent link="link2"/>
    <child link="bar0"/>
    <axis xyz="1 0 0"/>
    <origin rpy="0 0 0" xyz="0 0 0"/>
  </joint>
  <transmission name="trans_3">
    <type>transmission_interface/SimpleTransmission</type>
    <joint name="joint3">
      <hardwareInterface>hardware_interface/EffortJointInterface</hardwareInterface>
    </joint>
    <actuator name="motor_3">
      <hardwareInterface>hardware_interface/EffortJointInterface</hardwareInterface>
      <mechanicalReduction>1</mechanicalReduction>
    </actuator>
  </transmission>
  <link name="bar0">
    <visual>
      <origin rpy="0 0 0" xyz="0 0 0.025"/>
      <geometry>
        <cylinder length="0.05" radius="0.002"/>
      </geometry>
    </visual>
    <collision>
      <origin rpy="0 0 0" xyz="0 0 0.025"/>
      <geometry>
        <cylinder length="0.05" radius="0.002"/>
      </geometry>
    </collision>
    <inertial>
      <origin xyz="0 0 0.025"/>
      <mass value="4"/>
      <inertia ixx="0.00084" ixy="0" ixz="0" iyy="0.00084" iyz="0" izz="0.000008"/>
    </inertial>
  </link>

  <joint name="cable" type="prismatic">
    <parent link="bar0"/>
    <child link="bar"/>
    <axis xyz="0 0 1"/>
    <origin rpy="0 0 0" xyz="0 0 0.05"/>
    <limit effort="10000" lower="0" upper="2.0" velocity="10"/>
  </joint>
  <transmission name="trans_c">
    <type>transmission_interface/SimpleTransmission</type>
    <joint name="cable">
      <hardwareInterface>hardware_interface/PositionJointInterface</hardwareInterface>
    </joint>
    <actuator name="motor_c">
      <hardwareInterface>hardware_interface/PositionJointInterface</hardwareInterface>
      <mechanicalReduction>1</mechanicalReduction>
    </actuator>
  </transmission>
  <link name="bar">
    <visual>
      <origin rpy="0 0 0" xyz="0 0 0.25"/>
      <geometry>
        <cylinder length="0.5" radius="0.002"/>
      </geometry>
    </visual>
    <collision>
      <origin rpy="0 0 0" xyz="0 0 0.25"/>
      <geometry>
        <cylinder length="0.5" radius="0.002"/>
      </geometry>
    </collision>
    <inertial>
      <origin xyz="0 0 0.25"/>
      <mass value="4"/>
      <inertia ixx="0.084" ixy="0" ixz="0" iyy="0.084" iyz="0" izz="0.000008"/>
    </inertial>
  </link>

  <joint name="joint11" type="continuous">
    <origin rpy="0 0 0" xyz="0 0 0.5"/>
    <parent link="bar"/>
    <child link="link11"/>
    <axis xyz="0 1 0"/>
  </joint>
  <transmission name="trans_11">
    <type>transmission_interface/SimpleTransmission</type>
    <joint name="joint11">
      <hardwareInterface>hardware_interface/EffortJointInterface</hardwareInterface>
    </joint>
    <actuator name="motor_11">
      <hardwareInterface>hardware_interface/EffortJointInterface</hardwareInterface>
      <mechanicalReduction>1</mechanicalReduction>
    </actuator>
  </transmission>
  <link name="link11">
    <inertial>
      <mass value="0.025"/>
      <inertia ixx="5.8083e-4" ixy="0" ixz="0" iyy="3.0833e-5" iyz="0" izz="5.9083e-4"/>
    </inertial>
  </link>

  <joint name="joint22" type="continuous">
    <origin rpy="0 0 0" xyz="0 0 0"/>
    <parent link="link11"/>
    <child link="link22"/>
    <axis xyz="0 0 1"/>
  </joint>
  <transmission name="trans_22">
    <type>transmission_interface/SimpleTransmission</type>
    <joint name="joint22">
      <hardwareInterface>hardware_interface/EffortJointInterface</hardwareInterface>
    </joint>
    <actuator name="motor_22">
      <hardwareInterface>hardware_interface/EffortJointInterface</hardwareInterface>
      <mechanicalReduction>1</mechanicalReduction>
    </actuator>
  </transmission>
  <link name="link22">
    <inertial>
      <mass value="0.025"/>
      <inertia ixx="5.8083e-4" ixy="0" ixz="0" iyy="3.0833e-5" iyz="0" izz="5.9083e-4"/>
    </inertial>
  </link>

  <joint name="joint33" type="continuous">
    <origin rpy="0 0 0" xyz="0 0 0"/>
    <parent link="link22"/>
    <child link="payload"/>
    <axis xyz="1 0 0"/>
  </joint>
  <transmission name="trans_33">
    <type>transmission_interface/SimpleTransmission</type>
    <joint name="joint33">
      <hardwareInterface>hardware_interface/EffortJointInterface</hardwareInterface>
    </joint>
    <actuator name="motor_33">
      <hardwareInterface>hardware_interface/EffortJointInterface</hardwareInterface>
      <mechanicalReduction>1</mechanicalReduction>
    </actuator>
  </transmission>
  <link name="payload">
    <visual>
      <origin rpy="0 0 0" xyz="0 0 0.3"/>
      <geometry>
        <box size="0.12 0.8 0.6"/>
      </geometry>
      <material name="dark_grey">
        <color rgba="0.2 0.2 0.2 1.0"/>
      </material>
    </visual>
    <inertial>
      <mass value="70"/>
      <origin rpy="0 0 0" xyz="0 0 0.3"/>
      <inertia ixx="2.18" ixy="0" ixz="0" iyy="5.83" iyz="0" izz="3.82"/>
    </inertial>
    <collision>
      <origin rpy="0 0 0" xyz="0 0 0.3"/>
      <geometry>
        <box size="0.12 0.8 0.6"/>
      </geometry>
    </collision>
  </link>

  <gazebo reference="payload">
    <selfCollide>true</selfCollide>
    <mu1 value="1.2"/>
    <mu2 value="1.2"/>
  </gazebo>

  <transmission name="cart_trans">
    <type>transmission_interface/SimpleTransmission</type>
    <joint name="cart_joint">
      <hardwareInterface>hardware_interface/PositionJointInterface</hardwareInterface>
    </joint>
    <actuator name="cart_motor">
      <hardwareInterface>hardware_interface/PositionJointInterface</hardwareInterface>
      <mechanicalReduction>1</mechanicalReduction>
    </actuator>
  </transmission>

  <gazebo>
    <plugin filename="libgazebo_ros_control.so" name="gazebo_ros_control"/>
  </gazebo>
  <gazebo reference="base_link">
    <selfCollide>false</selfCollide>
    <mu1 value="0.05"/>
    <mu2 value="0.05"/>
  </gazebo>
  <gazebo reference="cart_link">
    <selfCollide>false</selfCollide>
    <mu1 value="1.2"/>
    <mu2 value="1.2"/>
  </gazebo>

</robot>
