<?xml version="1.0" encoding="utf-8"?>
<!-- =================================================================================== -->
<!-- |    This document is a hand edited version of the output autogenerated by xacro  | -->
<!-- |    from panda_arm_hand.urdf.xacro                                               | -->
<!-- |    The rotor inertias and gear ratios have been picked so that their            | -->
<!-- |    combination is equal to the reflected rotor interia provided by Franka for   | -->
<!-- |    the FR-3 robots.                                                             | -->
<!-- =================================================================================== -->
<robot name="panda">
  <link name="world"/>
  <joint name="robot_to_world" type="fixed">
    <parent link="world"/>
    <child link="panda_link0"/>
    <origin rpy="0.0 0.0 0.0" xyz="0.0 0.0 0.0"/>
  </joint>
  <link name="panda_link0">
    <inertial>
      <origin rpy="0 0 0" xyz="-0.041018 -0.00014 0.049974"/>
      <mass value="0.629769"/>
      <inertia ixx="0.00315" ixy="8.2904e-07" ixz="0.00015" iyy="0.00388" iyz="8.2299e-06" izz="0.004285"/>
    </inertial>
    <visual>
      <origin rpy="1.57079632679 0 0"/>
      <geometry>
        <mesh filename="../meshes/link0.obj"/>
      </geometry>
    </visual>
    <collision>
      <origin rpy="1.57079632679 0 0"/>
      <geometry>
        <mesh filename="../meshes/link0_simple.obj"/>
      </geometry>
      <drake:proximity_properties>
        <drake:rigid_hydroelastic/>
        <drake:mesh_resolution_hint value="1.5"/>
        <drake:hunt_crossley_dissipation value="1.25"/>
      </drake:proximity_properties>
    </collision>
  </link>

  <link name="panda_link1">
    <inertial>
      <origin rpy="0 0 0" xyz="-0.003141 -0.02872  0.003495"/>
      <mass value="0.646926"/>
      <inertia ixx="0.007962" ixy="-0.003925" ixz="0.010254" iyy="0.02811" iyz="0.000704" izz="0.025995"/>
    </inertial>
    <visual>
      <origin rpy="1.57079632679 0 0"/>
      <geometry>
        <mesh filename="../meshes/link1.obj"/>
      </geometry>
    </visual>
    <collision>
      <origin rpy="1.57079632679 0 0"/>
      <geometry>
        <mesh filename="../meshes/link1_simple.obj"/>
      </geometry>
      <drake:proximity_properties>
        <drake:rigid_hydroelastic/>
        <drake:mesh_resolution_hint value="1.5"/>
        <drake:hunt_crossley_dissipation value="1.25"/>
      </drake:proximity_properties>
    </collision>
  </link>

  <joint name="panda_joint1" type="revolute">
    <origin rpy="0 0 0" xyz="0 0 0.333"/>
    <parent link="panda_link0"/>
    <child link="panda_link1"/>
    <axis xyz="0 0 1"/>
    <limit effort="87" lower="-2.8973" upper="2.8973" velocity="2.1750"/>
  </joint>



  <link name="panda_link2">
    <inertial>
      <origin rpy="0 0 0" xyz="2.7518e-02 3.9252e-02 -6.6502e-02"/>
      <mass value="3.228604"/>
      <inertia ixx="0.037242" ixy="-0.004761" ixz="-0.011396" iyy="0.036155" iyz="-0.012805" izz="0.01083"/>
    </inertial>
    <visual>
      <origin rpy="1.57079632679 0 0"/>
      <geometry>
        <mesh filename="../meshes/link2.obj"/>
      </geometry>
    </visual>
    <collision>
      <origin rpy="1.57079632679 0 0"/>
      <geometry>
        <mesh filename="../meshes/link2_simple.obj"/>
      </geometry>
      <drake:proximity_properties>
        <drake:rigid_hydroelastic/>
        <drake:mesh_resolution_hint value="1.5"/>
        <drake:hunt_crossley_dissipation value="1.25"/>
      </drake:proximity_properties>
    </collision>
  </link>
  <joint name="panda_joint2" type="revolute">
    <origin rpy="-1.57079632679 0 0" xyz="0 0 0"/>
    <parent link="panda_link1"/>
    <child link="panda_link2"/>
    <axis xyz="0 0 1"/>
    <limit effort="87" lower="-1.7628" upper="1.7628" velocity="2.1750"/>
  </joint>

  <link name="panda_link3">
    <inertial>
      <origin rpy="0 0 0" xyz="-5.317e-02 1.04419e-01 2.7454e-02"/>
      <mass value="3.587895"/>
      <inertia ixx="0.025853" ixy="0.007796" ixz="-0.001332" iyy="0.019552" iyz="0.008641" izz="0.028323"/>
    </inertial>
    <visual>
      <origin rpy="1.57079632679 0 0"/>
      <geometry>
        <mesh filename="../meshes/link3.obj"/>
      </geometry>
    </visual>
    <collision>
      <origin rpy="1.57079632679 0 0"/>
      <geometry>
        <mesh filename="../meshes/link3_simple.obj"/>
      </geometry>
      <drake:proximity_properties>
        <drake:rigid_hydroelastic/>
        <drake:mesh_resolution_hint value="1.5"/>
        <drake:hunt_crossley_dissipation value="1.25"/>
      </drake:proximity_properties>
    </collision>
  </link>
  <joint name="panda_joint3" type="revolute">
    <origin rpy="1.57079632679 0 0" xyz="0 -0.316 0"/>
    <parent link="panda_link2"/>
    <child link="panda_link3"/>
    <axis xyz="0 0 1"/>
    <limit effort="87" lower="-2.8973" upper="2.8973" velocity="2.1750"/>
  </joint>
  <link name="panda_link4">
    <inertial>
      <origin rpy="0 0 0" xyz="-1.1953e-02 4.1065e-02 -3.8437e-02"/>
      <mass value="1.225946"/>
      <inertia ixx="0.035549" ixy="-0.002117" ixz="-0.004037" iyy="0.029474" iyz="0.000229" izz="0.008627"/>
    </inertial>
    <visual>
      <origin rpy="1.57079632679 0 0"/>
      <geometry>
        <mesh filename="../meshes/link4.obj"/>
      </geometry>
    </visual>
    <collision>
      <origin rpy="1.57079632679 0 0"/>
      <geometry>
        <mesh filename="../meshes/link4_simple.obj"/>
      </geometry>
      <drake:proximity_properties>
        <drake:rigid_hydroelastic/>
        <drake:mesh_resolution_hint value="1.5"/>
        <drake:hunt_crossley_dissipation value="1.25"/>
      </drake:proximity_properties>
    </collision>
  </link>
  <joint name="panda_joint4" type="revolute">
    <origin rpy="1.57079632679 0 0" xyz="0.0825 0 0"/>
    <parent link="panda_link3"/>
    <child link="panda_link4"/>
    <axis xyz="0 0 1"/>
    <limit effort="87" lower="-3.0718" upper="-0.0698" velocity="2.1750"/>
  </joint>
  <link name="panda_link5">
    <inertial>
      <origin rpy="0 0 0" xyz="6.0149e-02 -1.4117e-02 -1.0517e-02"/>
      <mass value="1.666555"/>
      <inertia ixx="0.001964" ixy="0.000109" ixz="-0.001158" iyy="0.004354" iyz="0.000341" izz="0.005433"/>
    </inertial>
    <visual>
      <origin rpy="1.57079632679 0 0"/>
      <geometry>
        <mesh filename="../meshes/link5.obj"/>
      </geometry>
    </visual>
    <collision>
      <origin rpy="1.57079632679 0 0"/>
      <geometry>
        <mesh filename="../meshes/link5_simple.obj"/>
      </geometry>
      <drake:proximity_properties>
        <drake:rigid_hydroelastic/>
        <drake:mesh_resolution_hint value="1.5"/>
        <drake:hunt_crossley_dissipation value="1.25"/>
      </drake:proximity_properties>
    </collision>
  </link>
  <joint name="panda_joint5" type="revolute">
    <origin rpy="-1.57079632679 0 0" xyz="-0.0825 0.384 0"/>
    <parent link="panda_link4"/>
    <child link="panda_link5"/>
    <axis xyz="0 0 1"/>
    <limit effort="12" lower="-2.8973" upper="2.8973" velocity="2.6100"/>
  </joint>
  <link name="panda_link6">
    <inertial>
      <origin rpy="0 0 0" xyz="1.0517e-02 -4.252e-03 6.1597e-02"/>
      <mass value="0.735522"/>
      <inertia ixx="0.012516" ixy="-0.000428" ixz="-0.001196" iyy="0.010027" iyz="-0.000741" izz="0.004815"/>
    </inertial>
    <visual>
      <origin rpy="1.57079632679 0 0"/>
      <geometry>
        <mesh filename="../meshes/link6.obj"/>
      </geometry>
    </visual>
    <collision>
      <origin rpy="1.57079632679 0 0"/>
      <geometry>
        <mesh filename="../meshes/link6_simple.obj"/>
      </geometry>
      <drake:proximity_properties>
        <drake:rigid_hydroelastic/>
        <drake:mesh_resolution_hint value="1.5"/>
        <drake:hunt_crossley_dissipation value="1.25"/>
      </drake:proximity_properties>
    </collision>
  </link>
  <joint name="panda_joint6" type="revolute">
    <origin rpy="1.57079632679 0 0" xyz="0 0 0"/>
    <parent link="panda_link5"/>
    <child link="panda_link6"/>
    <axis xyz="0 0 1"/>
    <limit effort="12" lower="-0.0175" upper="3.7525" velocity="2.610"/>
  </joint>
  <link name="panda_link7">
    <inertial>
      <origin rpy="0 0 0" xyz="1.0517e-02 -4.252e-03 6.1597e-02"/>
      <mass value="7.35522e-01"/>
      <inertia ixx="1.2516e-02" ixy="-4.2800e-04" ixz="-1.1960e-03" iyy="1.0027e-02" iyz="-7.4100e-04" izz="4.8150e-03"/>
    </inertial>
    <visual>
      <origin rpy="1.57079632679 0 0"/>
      <geometry>
        <mesh filename="../meshes/link7.obj"/>
      </geometry>
    </visual>
    <collision>
      <origin rpy="1.57079632679 0 0"/>
      <geometry>
        <mesh filename="../meshes/link7_simple.obj"/>
      </geometry>
      <drake:proximity_properties>
        <drake:rigid_hydroelastic/>
        <drake:mesh_resolution_hint value="1.5"/>
        <drake:hunt_crossley_dissipation value="1.25"/>
      </drake:proximity_properties>
    </collision>
  </link>
  <joint name="panda_joint7" type="revolute">
    <origin rpy="1.57079632679 0 0" xyz="0.088 0 0"/>
    <parent link="panda_link6"/>
    <child link="panda_link7"/>
    <axis xyz="0 0 1"/>
    <limit effort="12" lower="-2.8973" upper="2.8973" velocity="2.610"/>
  </joint>
  <link name="panda_link8"/>
  <joint name="panda_joint8" type="fixed">
    <origin rpy="0 0 0" xyz="0 0 0.107"/>
    <parent link="panda_link7"/>
    <child link="panda_link8"/>
  </joint>

  <!-- ========================================================== -->
  <!-- Macro to add a single link, both with                      -->
  <!--  * detailed meshes for environmental collision checking    -->
  <!--  * and coarse geometry models for self-collision checking  -->
  <!--    (only if 'gazebo' param is set)                         -->
  <!--                                                            -->
  <!-- name:  Name of the end-effector (without prefix)             -->
  <!-- rpy:   Rotation of the *_sc link relative to parent [rad]  -->
  <!-- self_collision_geometries:  self <collision> models        -->
  <!-- ========================================================== -->
  <joint name="panda_tray_shaped_joint" type="fixed">
    <parent link="panda_link8"/>
    <child link="panda_tray_shaped"/>
    <origin rpy="1.5707963267948966 0 2.356194490192345" xyz="0.11 -0.35 0"/>
  </joint>

<link name="panda_tray_shaped">
    <inertial>
      <origin rpy="0 0 0" xyz="0.175 0.1 0.175"/>
      <mass value="0.927"/>
      <inertia ixx="0.0066" ixy="-0.00165" ixz="0.00069" iyy="0.0066" iyz="-0.00069" izz="0.0122"/>
    </inertial>

  <visual>
    <geometry>
      <mesh filename="../meshes/tray_shaped_ee.obj"/>
    </geometry>
    <material>
    <diffuse>1.0 0.55 1.0 0.2</diffuse>
</material>
  </visual>

  <collision>
        <origin rpy="1.5707963267948966 0 0" xyz="0.175 0.107 0.175"/>
    <geometry>
      <!-- <mesh filename="../meshes/tray_shaped_ee.obj"/>-->
       <box size="0.4 0.4 0.005" />
    </geometry>
    <drake:proximity_properties>
      <drake:rigid_hydroelastic/>
      <drake:mesh_resolution_hint value="0.001"/>
      <drake:hunt_crossley_dissipation value="1.25"/>
    </drake:proximity_properties>
  </collision>
</link>

  <!-- Define the ${ee_id}_tcp frame -->
  <link name="panda_tray_shaped_tcp"/>
  <joint name="panda_tray_shaped_tcp_joint" type="fixed">
    <origin rpy="1.5707963267948966 0 0" xyz="0.175 0.105 0.175"/>
    <parent link="panda_tray_shaped"/>
    <child link="panda_tray_shaped_tcp"/>
  </joint>

  <transmission name="panda_tran1">
    <type>transmission_interface/SimpleTransmission</type>
    <joint name="panda_joint1">
      <hardwareInterface>hardware_interface/PositionJointInterface</hardwareInterface>
    </joint>
    <actuator name="panda_motor1">
      <hardwareInterface>hardware_interface/PositionJointInterface</hardwareInterface>
      <mechanicalReduction>1</mechanicalReduction>
      <drake:gear_ratio value="100.0" />
      <drake:rotor_inertia value="0.0000605721456" />
    </actuator>
  </transmission>

  <transmission name="panda_tran2">
    <type>transmission_interface/SimpleTransmission</type>
    <joint name="panda_joint2">
      <hardwareInterface>hardware_interface/PositionJointInterface</hardwareInterface>
    </joint>
    <actuator name="panda_motor2">
      <hardwareInterface>hardware_interface/PositionJointInterface</hardwareInterface>
      <mechanicalReduction>1</mechanicalReduction>
      <drake:gear_ratio value="100.0" />
      <drake:rotor_inertia value="0.0000605721456" />
    </actuator>
  </transmission>
  <transmission name="panda_tran3">
    <type>transmission_interface/SimpleTransmission</type>
    <joint name="panda_joint3">
      <hardwareInterface>hardware_interface/PositionJointInterface</hardwareInterface>
    </joint>
    <actuator name="panda_motor3">
      <hardwareInterface>hardware_interface/PositionJointInterface</hardwareInterface>
      <mechanicalReduction>1</mechanicalReduction>
      <drake:gear_ratio value="100.0" />
      <drake:rotor_inertia value="0.0000462474144" />
    </actuator>
  </transmission>
  <transmission name="panda_tran4">
    <type>transmission_interface/SimpleTransmission</type>
    <joint name="panda_joint4">
      <hardwareInterface>hardware_interface/PositionJointInterface</hardwareInterface>
    </joint>
    <actuator name="panda_motor4">
      <hardwareInterface>hardware_interface/PositionJointInterface</hardwareInterface>
      <mechanicalReduction>1</mechanicalReduction>
      <drake:gear_ratio value="100.0" />
      <drake:rotor_inertia value="0.0000462474144" />
    </actuator>
  </transmission>
  <transmission name="panda_tran5">
    <type>transmission_interface/SimpleTransmission</type>
    <joint name="panda_joint5">
      <hardwareInterface>hardware_interface/PositionJointInterface</hardwareInterface>
    </joint>
    <actuator name="panda_motor5">
      <hardwareInterface>hardware_interface/PositionJointInterface</hardwareInterface>
      <mechanicalReduction>1</mechanicalReduction>
      <drake:gear_ratio value="100.0" />
      <drake:rotor_inertia value="0.0000205544064" />
    </actuator>
  </transmission>
  <transmission name="panda_tran6">
    <type>transmission_interface/SimpleTransmission</type>
    <joint name="panda_joint6">
      <hardwareInterface>hardware_interface/PositionJointInterface</hardwareInterface>
    </joint>
    <actuator name="panda_motor6">
      <hardwareInterface>hardware_interface/PositionJointInterface</hardwareInterface>
      <mechanicalReduction>1</mechanicalReduction>
      <drake:gear_ratio value="100.0" />
      <drake:rotor_inertia value="0.0000205544064" />
    </actuator>
  </transmission>
  <transmission name="panda_tran7">
    <type>transmission_interface/SimpleTransmission</type>
    <joint name="panda_joint7">
      <hardwareInterface>hardware_interface/PositionJointInterface</hardwareInterface>
    </joint>
    <actuator name="panda_motor7">
      <hardwareInterface>hardware_interface/PositionJointInterface</hardwareInterface>
      <mechanicalReduction>1</mechanicalReduction>
      <drake:gear_ratio value="100.0" />
      <drake:rotor_inertia value="0.0000205544064" />
    </actuator>
  </transmission>
  <drake:collision_filter_group name="all">
    <drake:member link="panda_link0"/>
    <drake:member link="panda_link1"/>
    <drake:member link="panda_link2"/>
    <drake:member link="panda_link3"/>
    <drake:member link="panda_link4"/>
    <drake:member link="panda_link5"/>
    <drake:member link="panda_link6"/>
    <drake:member link="panda_link7"/>
    <drake:member link="panda_tray_shaped"/>
    <drake:ignored_collision_filter_group name="all"/>
  </drake:collision_filter_group>
</robot>
