<?xml version="1.0" encoding="utf-8"?>
<!-- =================================================================================== -->
<!-- |    This document is a hand edited version of the output autogenerated by xacro  | -->
<!-- |    from panda_arm_hand.urdf.xacro                                               | -->
<!-- |    The rotor inertias and gear ratios have been picked so that their            | -->
<!-- |    combination is equal to the reflected rotor interia provided by Franka for   | -->
<!-- |    the FR-3 robots.                                                             | -->
<!-- =================================================================================== -->
<robot name="panda">
  <link name="world"/>
  <joint name="robot_to_world" type="fixed">
    <parent link="world"/>
    <child link="panda_link0"/>
    <origin rpy="0.0 0.0 0.0" xyz="0.0 0.0 0.0"/>
  </joint>
  <link name="panda_link0">
    <inertial>
      <origin rpy="0 0 0" xyz="-0.0172 0.0004 0.0745"/>
      <mass value="2.3966"/>
      <inertia ixx="0.009" ixy="0.0" ixz="0.002" iyy="0.0115" iyz="0.0" izz="0.0085"/>
    </inertial>
    <visual>
      <origin rpy="1.57079632679 0 0"/>
      <geometry>
        <mesh filename="../meshes/link0.obj"/>
      </geometry>
    </visual>
    <collision>
      <origin rpy="1.57079632679 0 0"/>
      <geometry>
        <mesh filename="../meshes/link0_simple.obj"/>
      </geometry>
      <drake:proximity_properties>
        <drake:rigid_hydroelastic/>
        <drake:mesh_resolution_hint value="1.5"/>
        <drake:hunt_crossley_dissipation value="1.25"/>
      </drake:proximity_properties>
    </collision>
  </link>

  <link name="panda_link1">
    <!-- <inertial>
      <origin rpy="0 0 0" xyz="0.00033 -0.02204 -0.04762"/>
      <mass value="2.7907"/>
      <inertia ixx="0.01564782655" ixy="5.31236e-06" ixz="-3.676721e-05" iyy="0.01439883526" iyz="-0.00248480843" izz="0.00500443991"/>
    </inertial> -->
    <inertial>
        <origin rpy="0 0 0" xyz="-0.003875 0.002081 0.0" />
        <mass value="4.970684" />
        <inertia ixx="0.70337" ixy="-1.3900e-04" ixz="6.7720e-03" iyy="7.0661e-01" iyz="1.9169e-02" izz="9.1170e-03" />
    </inertial>

    <visual>
      <origin rpy="1.57079632679 0 0"/>
      <geometry>
        <mesh filename="../meshes/link1.obj"/>
      </geometry>
    </visual>
    <collision>
      <origin rpy="1.57079632679 0 0"/>
      <geometry>
        <mesh filename="../meshes/link1_simple.obj"/>
      </geometry>
      <drake:proximity_properties>
        <drake:rigid_hydroelastic/>
        <drake:mesh_resolution_hint value="1.5"/>
        <drake:hunt_crossley_dissipation value="1.25"/>
      </drake:proximity_properties>
    </collision>
  </link>

  <joint name="panda_joint1" type="revolute">
    <origin rpy="0 0 0" xyz="0 0 0.333"/>
    <parent link="panda_link0"/>
    <child link="panda_link1"/>
    <axis xyz="0 0 1"/>
    <limit effort="87" lower="-2.8973" upper="2.8973" velocity="2.1750"/>
  </joint>



  <link name="panda_link2">
    <!-- <inertial>
      <origin rpy="0 0 0" xyz="0.00038 -0.09211 0.01908"/>
      <mass value="2.542"/>
      <inertia ixx="0.01662427728" ixy="3.086077e-05" ixz="8.3594e-06" iyy="0.00462501261" iyz="0.0035589983" izz="0.01545124526"/>
    </inertial> -->
    <inertial>
            <origin rpy="0 0 0" xyz="-3.141e-03 -2.872e-02 3.495e-03" />
            <mass value="0.646926" />
            <inertia ixx="7.9620e-03" ixy="-3.9250e-03" ixz="1.0254e-02" iyy="2.8110e-02" iyz="7.0400e-04" izz="2.5995e-02" />
    </inertial>      
    <visual>
      <origin rpy="1.57079632679 0 0"/>
      <geometry>
        <mesh filename="../meshes/link2.obj"/>
      </geometry>
    </visual>
    <collision>
      <origin rpy="1.57079632679 0 0"/>
      <geometry>
        <mesh filename="../meshes/link2_simple.obj"/>
      </geometry>
      <drake:proximity_properties>
        <drake:rigid_hydroelastic/>
        <drake:mesh_resolution_hint value="1.5"/>
        <drake:hunt_crossley_dissipation value="1.25"/>
      </drake:proximity_properties>
    </collision>
  </link>
  <joint name="panda_joint2" type="revolute">
    <origin rpy="-1.57079632679 0 0" xyz="0 0 0"/>
    <parent link="panda_link1"/>
    <child link="panda_link2"/>
    <axis xyz="0 0 1"/>
    <limit effort="87" lower="-1.7628" upper="1.7628" velocity="2.1750"/>
  </joint>

  <link name="panda_link3">
    <!-- <inertial>
      <origin rpy="0 0 0" xyz="0.05152 0.01696 -0.02971"/>
      <mass value="2.2513"/>
      <inertia ixx="0.00631741992" ixy="0.00097309955" ixz="0.00292525834" iyy="0.00866285493" iyz="0.00093469224" izz="0.00657804051"/>
    </inertial> -->
    <inertial>
        <origin rpy="0 0 0" xyz="2.7518e-02 3.9252e-02 -6.6502e-02" />
        <mass value="3.228604" />
        <inertia ixx="3.7242e-02" ixy="-4.7610e-03" ixz="-1.1396e-02" iyy="3.6155e-02" iyz="-1.2805e-02" izz="1.0830e-02" />
    </inertial>
    <visual>
      <origin rpy="1.57079632679 0 0"/>
      <geometry>
        <mesh filename="../meshes/link3.obj"/>
      </geometry>
    </visual>
    <collision>
      <origin rpy="1.57079632679 0 0"/>
      <geometry>
        <mesh filename="../meshes/link3_simple.obj"/>
      </geometry>
      <drake:proximity_properties>
        <drake:rigid_hydroelastic/>
        <drake:mesh_resolution_hint value="1.5"/>
        <drake:hunt_crossley_dissipation value="1.25"/>
      </drake:proximity_properties>
    </collision>
  </link>
  <joint name="panda_joint3" type="revolute">
    <origin rpy="1.57079632679 0 0" xyz="0 -0.316 0"/>
    <parent link="panda_link2"/>
    <child link="panda_link3"/>
    <axis xyz="0 0 1"/>
    <limit effort="87" lower="-2.8973" upper="2.8973" velocity="2.1750"/>
  </joint>
  <link name="panda_link4">
    <!-- <inertial>
      <origin rpy="0 0 0" xyz="-0.05113 0.05825 0.01698"/>
      <mass value="2.2837"/>
      <inertia ixx="0.00784585566" ixy="-0.00339591957" ixz="0.00158704074" iyy="0.00649543136" iyz="-0.00181477884" izz="0.01003079917"/>
    </inertial> -->
    <inertial>
      <origin rpy="0 0 0" xyz="-5.317e-02 1.04419e-01 2.7454e-02" />
      <mass value="3.587895" />
      <inertia ixx="2.5853e-02" ixy="7.7960e-03" ixz="-1.3320e-03" iyy="1.9552e-02" iyz="8.6410e-03" izz="2.8323e-02" />
    </inertial>
    <visual>
      <origin rpy="1.57079632679 0 0"/>
      <geometry>
        <mesh filename="../meshes/link4.obj"/>
      </geometry>
    </visual>
    <collision>
      <origin rpy="1.57079632679 0 0"/>
      <geometry>
        <mesh filename="../meshes/link4_simple.obj"/>
      </geometry>
      <drake:proximity_properties>
        <drake:rigid_hydroelastic/>
        <drake:mesh_resolution_hint value="1.5"/>
        <drake:hunt_crossley_dissipation value="1.25"/>
      </drake:proximity_properties>
    </collision>
  </link>
  <joint name="panda_joint4" type="revolute">
    <origin rpy="1.57079632679 0 0" xyz="0.0825 0 0"/>
    <parent link="panda_link3"/>
    <child link="panda_link4"/>
    <axis xyz="0 0 1"/>
    <limit effort="87" lower="-3.0718" upper="-0.0698" velocity="2.1750"/>
  </joint>
  <link name="panda_link5">
    <!-- <inertial>
      <origin rpy="0 0 0" xyz="-0.00005 0.03730 -0.09280"/>
      <mass value="2.2855"/>
      <inertia ixx="0.02297014781" ixy="-0.00000949345" ixz="-0.00002063156" iyy="0.02095060919" iyz="0.00382345782" izz="0.00430606551"/>
    </inertial> -->
    <inertial>
      <origin rpy="0 0 0" xyz="-1.1953e-02 4.1065e-02 -3.8437e-02" />
      <mass value="1.225946" />
      <inertia ixx="3.5549e-02" ixy="-2.1170e-03" ixz="-4.0370e-03" iyy="2.9474e-02" iyz="2.2900e-04" izz="8.6270e-03" />
    </inertial>
    <visual>
      <origin rpy="1.57079632679 0 0"/>
      <geometry>
        <mesh filename="../meshes/link5.obj"/>
      </geometry>
    </visual>
    <collision>
      <origin rpy="1.57079632679 0 0"/>
      <geometry>
        <mesh filename="../meshes/link5_simple.obj"/>
      </geometry>
      <drake:proximity_properties>
        <drake:rigid_hydroelastic/>
        <drake:mesh_resolution_hint value="1.5"/>
        <drake:hunt_crossley_dissipation value="1.25"/>
      </drake:proximity_properties>
    </collision>
  </link>
  <joint name="panda_joint5" type="revolute">
    <origin rpy="-1.57079632679 0 0" xyz="-0.0825 0.384 0"/>
    <parent link="panda_link4"/>
    <child link="panda_link5"/>
    <axis xyz="0 0 1"/>
    <limit effort="12" lower="-2.8973" upper="2.8973" velocity="2.6100"/>
  </joint>
  <link name="panda_link6">
    <!-- <inertial>
      <origin rpy="0 0 0" xyz="0.06572 -0.00371 0.00153"/>
      <mass value="1.353"/>
      <inertia ixx="0.00087964522" ixy="-0.00021487814" ixz="-0.00011911662" iyy="0.00277796968" iyz="1.274322e-05" izz="0.00286701969"/>
    </inertial> -->
    <inertial>
      <origin rpy="0 0 0" xyz="6.0149e-02 -1.4117e-02 -1.0517e-02" />
      <mass value="1.666555" />
      <inertia ixx="1.9640e-03" ixy="1.0900e-04" ixz="-1.1580e-03" iyy="4.3540e-03" iyz="3.4100e-04" izz="5.4330e-03" />
    </inertial>      
    <visual>
      <origin rpy="1.57079632679 0 0"/>
      <geometry>
        <mesh filename="../meshes/link6.obj"/>
      </geometry>
    </visual>
    <collision>
      <origin rpy="1.57079632679 0 0"/>
      <geometry>
        <mesh filename="../meshes/link6_simple.obj"/>
      </geometry>
      <drake:proximity_properties>
        <drake:rigid_hydroelastic/>
        <drake:mesh_resolution_hint value="1.5"/>
        <drake:hunt_crossley_dissipation value="1.25"/>
      </drake:proximity_properties>
    </collision>
  </link>
  <joint name="panda_joint6" type="revolute">
    <origin rpy="1.57079632679 0 0" xyz="0 0 0"/>
    <parent link="panda_link5"/>
    <child link="panda_link6"/>
    <axis xyz="0 0 1"/>
    <limit effort="12" lower="-0.0175" upper="3.7525" velocity="2.610"/>
  </joint>
  <link name="panda_link7">
    <!-- <inertial>
      <origin rpy="0 0 0" xyz="0.00089 -0.00044 0.05491"/>
      <mass value="0.35973"/>
      <inertia ixx="0.00019541063" ixy="0.00000165231" ixz="0.00000148826" iyy="0.00019210361" iyz="-0.00000131132" izz="0.00017936256"/>
    </inertial> -->
    <inertial>
      <origin rpy="0 0 0" xyz="1.0517e-02 -4.252e-03 6.1597e-02" />
      <mass value="7.35522e-01" />
      <inertia ixx="1.2516e-02" ixy="-4.2800e-04" ixz="-1.1960e-03" iyy="1.0027e-02" iyz="-7.4100e-04" izz="4.8150e-03" />
    </inertial>
    <visual>
      <origin rpy="1.57079632679 0 0"/>
      <geometry>
        <mesh filename="../meshes/link7.obj"/>
      </geometry>
    </visual>
    <collision>
      <origin rpy="1.57079632679 0 0"/>
      <geometry>
        <mesh filename="../meshes/link7_simple.obj"/>
      </geometry>
      <drake:proximity_properties>
        <drake:rigid_hydroelastic/>
        <drake:mesh_resolution_hint value="1.5"/>
        <drake:hunt_crossley_dissipation value="1.25"/>
      </drake:proximity_properties>
    </collision>
  </link>
  <joint name="panda_joint7" type="revolute">
    <origin rpy="1.57079632679 0 0" xyz="0.088 0 0"/>
    <parent link="panda_link6"/>
    <child link="panda_link7"/>
    <axis xyz="0 0 1"/>
    <limit effort="12" lower="-2.8973" upper="2.8973" velocity="2.610"/>
  </joint>
  <link name="panda_link8"/>
  <joint name="panda_joint8" type="fixed">
    <origin rpy="0 0 0" xyz="0 0 0.107"/>
    <parent link="panda_link7"/>
    <child link="panda_link8"/>
  </joint>

  <!-- ========================================================== -->
  <!-- Macro to add a single link, both with                      -->
  <!--  * detailed meshes for environmental collision checking    -->
  <!--  * and coarse geometry models for self-collision checking  -->
  <!--    (only if 'gazebo' param is set)                         -->
  <!--                                                            -->
  <!-- name:  Name of the end-effector (without prefix)             -->
  <!-- rpy:   Rotation of the *_sc link relative to parent [rad]  -->
  <!-- self_collision_geometries:  self <collision> models        -->
  <!-- ========================================================== -->
  <joint name="panda_tray_shaped_joint" type="fixed">
    <parent link="panda_link8"/>
    <child link="panda_tray_shaped"/>
    <origin rpy="1.5707963267948966 0 2.356194490192345" xyz="0.11604 -0.3637 0"/>
  </joint>

<link name="panda_tray_shaped">
  <inertial>
      <origin rpy="0 0 0" xyz="0.21626 0.08175 0.17501"/>
      <mass value="0.927"/>
      <inertia ixx="0.0078005609" ixy="-0.00125569249" ixz="0.00000155448" iyy="0.01921704298" iyz="-0.00000065173" izz="0.01259091335"/>
  </inertial>

  <visual>
    <geometry>
      <mesh filename="../meshes/tray_shaped_ee.obj"/>
    </geometry>
    <material>
      <diffuse>1.0 0.55 1.0 0.2</diffuse>
    </material>
  </visual>

  <collision>
    <geometry>
      <mesh filename="../meshes/tray_shaped_ee.obj"/>
    </geometry>
    <drake:proximity_properties>
      <drake:rigid_hydroelastic/>
      <drake:mesh_resolution_hint value="0.001"/>
      <drake:hunt_crossley_dissipation value="1.25"/>
    </drake:proximity_properties>
  </collision>
</link>

  <!-- Define the ${ee_id}_tcp frame -->
  <link name="panda_tray_shaped_tcp"/>
  <joint name="panda_tray_shaped_tcp_joint" type="fixed">
    <origin rpy="1.5707963267948966 0 0" xyz="0.175 0.105 0.175"/>
    <parent link="panda_tray_shaped"/>
    <child link="panda_tray_shaped_tcp"/>
  </joint>

  <transmission name="panda_tran1">
    <type>transmission_interface/SimpleTransmission</type>
    <joint name="panda_joint1">
      <hardwareInterface>hardware_interface/PositionJointInterface</hardwareInterface>
    </joint>
    <actuator name="panda_motor1">
      <hardwareInterface>hardware_interface/PositionJointInterface</hardwareInterface>
      <mechanicalReduction>1</mechanicalReduction>
      <drake:gear_ratio value="100.0" />
      <drake:rotor_inertia value="0.0000605721456" />
    </actuator>
  </transmission>

  <transmission name="panda_tran2">
    <type>transmission_interface/SimpleTransmission</type>
    <joint name="panda_joint2">
      <hardwareInterface>hardware_interface/PositionJointInterface</hardwareInterface>
    </joint>
    <actuator name="panda_motor2">
      <hardwareInterface>hardware_interface/PositionJointInterface</hardwareInterface>
      <mechanicalReduction>1</mechanicalReduction>
      <drake:gear_ratio value="100.0" />
      <drake:rotor_inertia value="0.0000605721456" />
    </actuator>
  </transmission>
  <transmission name="panda_tran3">
    <type>transmission_interface/SimpleTransmission</type>
    <joint name="panda_joint3">
      <hardwareInterface>hardware_interface/PositionJointInterface</hardwareInterface>
    </joint>
    <actuator name="panda_motor3">
      <hardwareInterface>hardware_interface/PositionJointInterface</hardwareInterface>
      <mechanicalReduction>1</mechanicalReduction>
      <drake:gear_ratio value="100.0" />
      <drake:rotor_inertia value="0.0000462474144" />
    </actuator>
  </transmission>
  <transmission name="panda_tran4">
    <type>transmission_interface/SimpleTransmission</type>
    <joint name="panda_joint4">
      <hardwareInterface>hardware_interface/PositionJointInterface</hardwareInterface>
    </joint>
    <actuator name="panda_motor4">
      <hardwareInterface>hardware_interface/PositionJointInterface</hardwareInterface>
      <mechanicalReduction>1</mechanicalReduction>
      <drake:gear_ratio value="100.0" />
      <drake:rotor_inertia value="0.0000462474144" />
    </actuator>
  </transmission>
  <transmission name="panda_tran5">
    <type>transmission_interface/SimpleTransmission</type>
    <joint name="panda_joint5">
      <hardwareInterface>hardware_interface/PositionJointInterface</hardwareInterface>
    </joint>
    <actuator name="panda_motor5">
      <hardwareInterface>hardware_interface/PositionJointInterface</hardwareInterface>
      <mechanicalReduction>1</mechanicalReduction>
      <drake:gear_ratio value="100.0" />
      <drake:rotor_inertia value="0.0000205544064" />
    </actuator>
  </transmission>
  <transmission name="panda_tran6">
    <type>transmission_interface/SimpleTransmission</type>
    <joint name="panda_joint6">
      <hardwareInterface>hardware_interface/PositionJointInterface</hardwareInterface>
    </joint>
    <actuator name="panda_motor6">
      <hardwareInterface>hardware_interface/PositionJointInterface</hardwareInterface>
      <mechanicalReduction>1</mechanicalReduction>
      <drake:gear_ratio value="100.0" />
      <drake:rotor_inertia value="0.0000205544064" />
    </actuator>
  </transmission>
  <transmission name="panda_tran7">
    <type>transmission_interface/SimpleTransmission</type>
    <joint name="panda_joint7">
      <hardwareInterface>hardware_interface/PositionJointInterface</hardwareInterface>
    </joint>
    <actuator name="panda_motor7">
      <hardwareInterface>hardware_interface/PositionJointInterface</hardwareInterface>
      <mechanicalReduction>1</mechanicalReduction>
      <drake:gear_ratio value="100.0" />
      <drake:rotor_inertia value="0.0000205544064" />
    </actuator>
  </transmission>
  <drake:collision_filter_group name="all">
    <drake:member link="panda_link0"/>
    <drake:member link="panda_link1"/>
    <drake:member link="panda_link2"/>
    <drake:member link="panda_link3"/>
    <drake:member link="panda_link4"/>
    <drake:member link="panda_link5"/>
    <drake:member link="panda_link6"/>
    <drake:member link="panda_link7"/>
    <drake:member link="panda_tray_shaped"/>
    <drake:ignored_collision_filter_group name="all"/>
  </drake:collision_filter_group>
</robot>
