<?xml version="1.0" encoding="utf-8"?>
<!-- =================================================================================== -->
<!-- |    This document was autogenerated by xacro from panda_arm_hand.urdf.xacro      | -->
<!-- |    EDITING THIS FILE BY HAND IS NOT RECOMMENDED                                 | -->
<!-- =================================================================================== -->
<robot name="panda">
  <link name="world"/>
  <joint name="robot_to_world" type="fixed">
    <parent link="world"/>
    <child link="panda_link0"/>
    <origin rpy="0.0 0.0 0.0" xyz="0.0 0.0 0.0"/>
  </joint>
  <link name="panda_link0">
    <visual>
      <geometry>
        <mesh filename="../meshes/visual/link0.obj"/>
      </geometry>
    </visual>
    <collision>
      <geometry>
        <mesh filename="../meshes/collision/link0.obj"/>
      </geometry>
    </collision>
    <inertial>
      <origin rpy="0 0 0" xyz="-0.0172 0.0004 0.0745"/>
      <mass value="2.3966"/>
      <inertia ixx="0.009" ixy="0.0" ixz="0.002" iyy="0.0115" iyz="0.0" izz="0.0085"/>
    </inertial>
  </link>
  <link name="panda_link1">
    <visual>
      <geometry>
        <mesh filename="../meshes/visual/link1.obj"/>
      </geometry>
    </visual>
    <collision>
      <geometry>
        <mesh filename="../meshes/collision/link1.obj"/>
      </geometry>
    </collision>
    <inertial>
      <origin rpy="0 0 0" xyz="0.00033 -0.02204 -0.04762"/>
      <mass value="2.7907"/>
      <inertia ixx="0.01564782655" ixy="5.31236e-06" ixz="-3.676721e-05" iyy="0.01439883526" iyz="-0.00248480843" izz="0.00500443991"/>
    </inertial>
  </link>
  <joint name="panda_joint1" type="revolute">
    <origin rpy="0 0 0" xyz="0 0 0.333"/>
    <parent link="panda_link0"/>
    <child link="panda_link1"/>
    <axis xyz="0 0 1"/>
    <limit effort="87" lower="-2.8973" upper="2.8973" velocity="2.1750"/>
    <dynamics damping="0.033333" friction="0" mu_coulomb="0" mu_viscous="16" />
  </joint>
  <link name="panda_link2">
    <visual>
      <geometry>
        <mesh filename="../meshes/visual/link2.obj"/>
      </geometry>
    </visual>
    <collision>
      <geometry>
        <mesh filename="../meshes/collision/link2.obj"/>
      </geometry>
    </collision>
    <inertial>
      <origin rpy="0 0 0" xyz="0.00038 -0.09211 0.01908"/>
      <mass value="2.542"/>
      <inertia ixx="0.01662427728" ixy="3.086077e-05" ixz="8.3594e-06" iyy="0.00462501261" iyz="0.0035589983" izz="0.01545124526"/>
    </inertial>
  </link>
  <joint name="panda_joint2" type="revolute">
    <origin rpy="-1.57079632679 0 0" xyz="0 0 0"/>
    <parent link="panda_link1"/>
    <child link="panda_link2"/>
    <axis xyz="0 0 1"/>
    <limit effort="87" lower="-1.7628" upper="1.7628" velocity="2.1750"/>
    <dynamics damping="0.033333" friction="0" mu_coulomb="0" mu_viscous="16" />
  </joint>
  <link name="panda_link3">
    <visual>
      <geometry>
        <mesh filename="../meshes/visual/link3.obj"/>
      </geometry>
    </visual>
    <collision>
      <geometry>
        <mesh filename="../meshes/collision/link3.obj"/>
      </geometry>
    </collision>
    <inertial>
      <origin rpy="0 0 0" xyz="0.05152 0.01696 -0.02971"/>
      <mass value="2.2513"/>
      <inertia ixx="0.00771376630908" ixy="-0.00248490625138" ixz="-0.00332147581033" iyy="0.00989108008727" iyz="-0.00217796151484" izz="0.00811723558464"/>
      <!-- <inertia ixx="0.00631741992" ixy="0.00097309955" ixz="0.00292525834" iyy="0.00866285493" iyz="0.00093469224" izz="0.00657804051"/> -->
    </inertial>
  </link>
  <joint name="panda_joint3" type="revolute">
    <origin rpy="1.57079632679 0 0" xyz="0 -0.316 0"/>
    <parent link="panda_link2"/>
    <child link="panda_link3"/>
    <axis xyz="0 0 1"/>
    <limit effort="87" lower="-2.8973" upper="2.8973" velocity="2.1750"/>
    <dynamics damping="0.033333" friction="0" mu_coulomb="0" mu_viscous="16" />
  </joint>
  <link name="panda_link4">
    <visual>
      <geometry>
        <mesh filename="../meshes/visual/link4.obj"/>
      </geometry>
    </visual>
    <collision>
      <geometry>
        <mesh filename="../meshes/collision/link4.obj"/>
      </geometry>
    </collision>
    <inertial>
      <origin rpy="0 0 0" xyz="-0.05113 0.05825 0.01698"/>
      <mass value="2.2037"/>
      <!-- <inertia ixx="0.00784585566" ixy="-0.00339591957" ixz="0.00158704074" iyy="0.00649543136" iyz="-0.00181477884" izz="0.01003079917"/> -->
      <inertia ixx="0.00799663881132" ixy="0.00347095570217" ixz="-0.00241222942995" iyy="0.00825390705278" iyz="0.00235774044121" izz="0.0102515004345"/>
    </inertial>
  </link>
  <joint name="panda_joint4" type="revolute">
    <origin rpy="1.57079632679 0 0" xyz="0.0825 0 0"/>
    <parent link="panda_link3"/>
    <child link="panda_link4"/>
    <axis xyz="0 0 1"/>
    <limit effort="87" lower="-3.0718" upper="-0.0698" velocity="2.1750"/>
    <dynamics damping="0.033333" friction="0" mu_coulomb="0" mu_viscous="16" />
  </joint>
  <link name="panda_link5">
    <visual>
      <geometry>
        <mesh filename="../meshes/visual/link5.obj"/>
      </geometry>
    </visual>
    <collision>
      <geometry>
        <mesh filename="../meshes/collision/link5.obj"/>
      </geometry>
    </collision>
    <inertial>
      <origin rpy="0 0 0" xyz="-0.00005 0.03730 -0.09280"/>
      <mass value="2.2855"/>
      <inertia ixx="0.02297014781" ixy="-9.49345e-06" ixz="-2.063156e-05" iyy="0.02095060919" iyz="0.00382345782" izz="0.00430606551"/>
    </inertial>
  </link>
  <joint name="panda_joint5" type="revolute">
    <origin rpy="-1.57079632679 0 0" xyz="-0.0825 0.384 0"/>
    <parent link="panda_link4"/>
    <child link="panda_link5"/>
    <axis xyz="0 0 1"/>
    <limit effort="12" lower="-2.8973" upper="2.8973" velocity="2.6100"/>
    <dynamics damping="0.033333" friction="0" mu_coulomb="0" mu_viscous="16" />
  </joint>
  <link name="panda_link6">
    <visual>
      <geometry>
        <mesh filename="../meshes/visual/link6.obj"/>
      </geometry>
    </visual>
    <collision>
      <geometry>
        <mesh filename="../meshes/collision/link6.obj"/>
      </geometry>
    </collision>
    <inertial>
      <origin rpy="0 0 0" xyz="0.06572 -0.00371 0.00153"/>
      <mass value="1.353"/>
      <inertia ixx="0.00087964522" ixy="-0.00021487814" ixz="-0.00011911662" iyy="0.00277796968" iyz="1.274322e-05" izz="0.00286701969"/>
    </inertial>
  </link>
  <joint name="panda_joint6" type="revolute">
    <origin rpy="1.57079632679 0 0" xyz="0 0 0"/>
    <parent link="panda_link5"/>
    <child link="panda_link6"/>
    <axis xyz="0 0 1"/>
    <limit effort="12" lower="-0.0175" upper="3.7525" velocity="2.6100"/>
    <dynamics damping="0.033333" friction="0" mu_coulomb="0" mu_viscous="16" />
  </joint>
  <link name="panda_link7">
    <visual>
      <geometry>
        <mesh filename="../meshes/visual/link7.obj"/>
      </geometry>
    </visual>
    <collision>
      <geometry>
        <mesh filename="../meshes/collision/link7.obj"/>
      </geometry>
    </collision>
    <inertial>
      <origin rpy="0 0 0" xyz="0.00089 -0.00044 0.05491"/>
      <mass value="0.35973"/>
      <inertia ixx="0.00019541063" ixy="1.65231e-06" ixz="1.48826e-06" iyy="0.00019210361" iyz="-1.31132e-06" izz="0.00017936256"/>
    </inertial>
  </link>
  <joint name="panda_joint7" type="revolute">
    <origin rpy="1.57079632679 0 0" xyz="0.088 0 0"/>
    <parent link="panda_link6"/>
    <child link="panda_link7"/>
    <axis xyz="0 0 1"/>
    <limit effort="12" lower="-2.8973" upper="2.8973" velocity="2.6100"/>
    <dynamics damping="0.033333" friction="0" mu_coulomb="0" mu_viscous="16"/>
  </joint>
  <link name="panda_link8">
    <!-- <inertial>
      <origin rpy="0 0 0" xyz="0 0 0"/>
      <mass value="0.1"/>
      <inertia ixx="0.3" ixy="0.0" ixz="0.0" iyy="0.3" iyz="0.0" izz="0.3"/>
    </inertial> -->
  </link>
  <joint name="panda_joint8" type="fixed">
    <origin rpy="0 0 0" xyz="0 0 0.107"/>
    <parent link="panda_link7"/>
    <child link="panda_link8"/>
    <axis xyz="1 0 0"/>
  </joint>

  <!-- ========================================================== -->
  <!-- Macro to add a single link, both with                      -->
  <!--  * detailed meshes for environmental collision checking    -->
  <!--  * and coarse geometry models for self-collision checking  -->
  <!--    (only if 'gazebo' param is set)                         -->
  <!--                                                            -->
  <!-- name:  Name of the end-effector (without prefix)             -->
  <!-- rpy:   Rotation of the *_sc link relative to parent [rad]  -->
  <!-- self_collision_geometries:  self <collision> models        -->
  <!-- ========================================================== -->
  <joint name="panda_tray_shaped_joint" type="fixed">
    <parent link="panda_link8"/>
    <child link="panda_tray_shaped"/>
    <origin rpy="1.5707963267948966 0 2.356194490192345" xyz="0.11604 -0.3637 0"/>
  </joint>

<link name="panda_tray_shaped">
    <inertial>
      <origin rpy="0 0 0" xyz="0.21626 0.08175 0.17501"/>
      <mass value="0.927"/>
          <inertia
      ixx="0.0078005609" ixy="-0.00125569249" ixz="0.00000155448"
      iyy="0.01921704298" iyz="-0.00000065173"
      izz="0.01259091335"/>
    </inertial>

  <visual>
    <geometry>
      <mesh filename="../meshes/planar_end_eff.obj" scale="0.001 0.001 0.001"/>
    </geometry>
    <!-- <material>
    <diffuse>1.0 0.55 1.0 0.2</diffuse>
</material> -->
  </visual>

  <collision>
        <origin rpy="1.5707963267948966 0 0" xyz="0.175 0.0927 0.175"/>
    <geometry>
      <!-- <mesh filename="../meshes/tray_shaped_ee.obj"/>-->
       <box size="0.35 0.35 0.005" />
    </geometry>
  </collision>
</link>

  <!-- Define the ${ee_id}_tcp frame -->
  <link name="panda_tray_shaped_tcp"/>
  <joint name="panda_tray_shaped_tcp_joint" type="fixed">
    <origin rpy="1.5707963267948966 0 0" xyz="0.175 0.0925 0.175"/>
    <parent link="panda_tray_shaped"/>
    <child link="panda_tray_shaped_tcp"/>
  </joint>

  <transmission name="panda_tran1">
    <type>transmission_interface/SimpleTransmission</type>
    <joint name="panda_joint1">
      <hardwareInterface>hardware_interface/PositionJointInterface</hardwareInterface>
    </joint>
    <actuator name="panda_motor1">
      <hardwareInterface>hardware_interface/PositionJointInterface</hardwareInterface>
      <mechanicalReduction>1</mechanicalReduction>
    </actuator>
  </transmission>

  <transmission name="panda_tran2">
    <type>transmission_interface/SimpleTransmission</type>
    <joint name="panda_joint2">
      <hardwareInterface>hardware_interface/PositionJointInterface</hardwareInterface>
    </joint>
    <actuator name="panda_motor2">
      <hardwareInterface>hardware_interface/PositionJointInterface</hardwareInterface>
      <mechanicalReduction>1</mechanicalReduction>
    </actuator>
  </transmission>
  <transmission name="panda_tran3">
    <type>transmission_interface/SimpleTransmission</type>
    <joint name="panda_joint3">
      <hardwareInterface>hardware_interface/PositionJointInterface</hardwareInterface>
    </joint>
    <actuator name="panda_motor3">
      <hardwareInterface>hardware_interface/PositionJointInterface</hardwareInterface>
      <mechanicalReduction>1</mechanicalReduction>
    </actuator>
  </transmission>
  <transmission name="panda_tran4">
    <type>transmission_interface/SimpleTransmission</type>
    <joint name="panda_joint4">
      <hardwareInterface>hardware_interface/PositionJointInterface</hardwareInterface>
    </joint>
    <actuator name="panda_motor4">
      <hardwareInterface>hardware_interface/PositionJointInterface</hardwareInterface>
      <mechanicalReduction>1</mechanicalReduction>
    </actuator>
  </transmission>
  <transmission name="panda_tran5">
    <type>transmission_interface/SimpleTransmission</type>
    <joint name="panda_joint5">
      <hardwareInterface>hardware_interface/PositionJointInterface</hardwareInterface>
    </joint>
    <actuator name="panda_motor5">
      <hardwareInterface>hardware_interface/PositionJointInterface</hardwareInterface>
      <mechanicalReduction>1</mechanicalReduction>
    </actuator>
  </transmission>
  <transmission name="panda_tran6">
    <type>transmission_interface/SimpleTransmission</type>
    <joint name="panda_joint6">
      <hardwareInterface>hardware_interface/PositionJointInterface</hardwareInterface>
    </joint>
    <actuator name="panda_motor6">
      <hardwareInterface>hardware_interface/PositionJointInterface</hardwareInterface>
      <mechanicalReduction>1</mechanicalReduction>
    </actuator>
  </transmission>
  <transmission name="panda_tran7">
    <type>transmission_interface/SimpleTransmission</type>
    <joint name="panda_joint7">
      <hardwareInterface>hardware_interface/PositionJointInterface</hardwareInterface>
    </joint>
    <actuator name="panda_motor7">
      <hardwareInterface>hardware_interface/PositionJointInterface</hardwareInterface>
      <mechanicalReduction>1</mechanicalReduction>
    </actuator>
  </transmission>
  <!-- <drake:collision_filter_group name="all">
    <drake:member link="panda_link0"/>
    <drake:member link="panda_link1"/>
    <drake:member link="panda_link2"/>
    <drake:member link="panda_link3"/>
    <drake:member link="panda_link4"/>
    <drake:member link="panda_link5"/>
    <drake:member link="panda_link6"/>
    <drake:member link="panda_link7"/>
    <drake:member link="panda_tray_shaped"/>
    <drake:ignored_collision_filter_group name="all"/>
  </drake:collision_filter_group> -->
</robot>
